Workbook

Sheet Dashboard
A1: DASHBOARD LAPORAN KEUANGAN
A2: SPPG Battuwinangun - Program Pemenuhan Gizi
A3: Periode: | B3: =TEXT(Pengaturan!B3,"dd mmm yyyy")&" s/d "&TEXT(Pengaturan!B4,"dd mmm yyyy")
A5: TOTAL DANA ANGGARAN | B5: TOTAL DIPAKAI | C5: TOTAL SISA DANA | D5: % PENYERAPAN
A6: =Pengaturan!B10 | B6: ='Pengeluaran Pangan'!G125+'Pengeluaran Operasional'!G123 | C6: =A6-B6 | D6: =IF(A6=0,0,B6/A6)
A8: A. PENGELUARAN BAHAN PANGAN
A9: Rata-Rata Pengeluaran Bahan Pangan / Hari | B9: =IFERROR('Pengeluaran Pangan'!G125/Pengaturan!B5,0)
A10: Pengeluaran Bahan Pangan Seharusnya / Hari | B10: =Pengaturan!B13
A11: Selisih Pengeluaran Bahan Pangan / Hari | B11: =B10-B9 | C11: (positif = hemat)
A13: Dana Total Bahan Pangan | B13: =Pengaturan!B8
A14: Penggunaan Dana Pangan | B14: ='Pengeluaran Pangan'!G125
A15: Sisa Dana Pangan | B15: =B13-B14
A16: % Penggunaan Dana Pangan | B16: =IF(B13=0,0,B14/B13)
A18: B. PENGELUARAN OPERASIONAL
A19: Rata-Rata Pengeluaran Operasional / Hari | B19: =IFERROR('Pengeluaran Operasional'!G123/Pengaturan!B5,0)
A20: Pengeluaran Operasional Seharusnya / Hari | B20: =Pengaturan!B14
A21: Selisih Pengeluaran Operasional / Hari | B21: =B20-B19 | C21: (positif = hemat)
A23: Dana Total Operasional | B23: =Pengaturan!B9
A24: Penggunaan Dana Operasional | B24: ='Pengeluaran Operasional'!G123
A25: Sisa Dana Operasional | B25: =B23-B24
A26: % Penggunaan Dana Operasional | B26: =IF(B23=0,0,B24/B23)
A28: C. RINGKASAN TOTAL
A29: Total Dana Anggaran | B29: =B13+B23
A30: Total Penggunaan Dana | B30: =B14+B24
A31: Total Sisa Dana | B31: =B29-B30
A32: % Penyerapan Anggaran | B32: =IF(B29=0,0,B30/B29)
A34: Rata-Rata Total Pengeluaran / Hari | B34: =B9+B19
A35: Pagu Total / Hari (Seharusnya) | B35: =Pengaturan!B15
A36: Selisih Total / Hari | B36: =B35-B34 | C36: (positif = hemat)
A38: D. ANALISIS SURPLUS/DEFISIT
A39: Jumlah Hari SURPLUS (hemat) | B39: =COUNTIF('Rekap Harian'!N6:N36,"SURPLUS")
A40: Jumlah Hari DEFISIT (boros) | B40: =COUNTIF('Rekap Harian'!N6:N36,"DEFISIT")
A41: Jumlah Hari AMAN (pas pagu) | B41: =COUNTIF('Rekap Harian'!N6:N36,"AMAN")
A43: Total Akumulasi Surplus | B43: =SUMIF('Rekap Harian'!M6:M36,">0")
A44: Total Akumulasi Defisit | B44: =SUMIF('Rekap Harian'!M6:M36,"<0")
A45: Net Surplus/Defisit | B45: =B43+B44
A47: Pengeluaran Tertinggi/Hari | B47: =MAX('Rekap Harian'!L6:L36)
A48: Pengeluaran Terendah/Hari | B48: =MINIFS('Rekap Harian'!L6:L36,'Rekap Harian'!L6:L36,">0")
A50: CATATAN:
A51: - Dashboard update otomatis dari sheet lain. Edit hanya di Pengaturan, Pagu Harian, & Log Pengeluaran.
...

Sheet Rekap Harian
A1: REKAP HARIAN PENGELUARAN
A2: Setiap hari akan dihitung otomatis: pagu, aktual, selisih, dan status surplus/defisit
A3: Periode: | B3: =TEXT(Pengaturan!B3,"dd mmm yyyy")&" s/d "&TEXT(Pengaturan!B4,"dd mmm yyyy")
A5: No | B5: Tanggal | C5: Hari | D5: Mg Ke | E5: Pagu Pangan | F5: Aktual Pangan | G5: Selisih Pangan | H5: Pagu Operasional | I5: Aktual Operasional | J5: Selisih Operasional | K5: Total Pagu | L5: Total Aktual | M5: Surplus/Defisit | N5: Status
A6: 1 | B6: =IF(Pengaturan!$B$3+0>Pengaturan!$B$4,"",Pengaturan!$B$3+0) | C6: =IF(B6="","",TEXT(B6,"dddd")) | D6: =IF(B6="","",INT((B6-Pengaturan!$B$3)/7)+1) | E6: =IFERROR(VLOOKUP(B6,'Pagu Harian'!$A$4:$D$40,2,FALSE),Pengaturan!$B$13) | F6: =IF(B6="",0,SUMIF('Pengeluaran Pangan'!A:A,B6,'Pengeluaran Pangan'!G:G)) | G6: =IF(B6="",0,E6-F6) | H6: =IFERROR(VLOOKUP(B6,'Pagu Harian'!$A$4:$D$40,3,FALSE),Pengaturan!$B$14) | I6: =IF(B6="",0,SUMIF('Pengeluaran Operasional'!A:A,B6,'Pengeluaran Operasional'!G:G)) | J6: =IF(B6="",0,H6-I6) | K6: =E6+H6 | L6: =F6+I6 | M6: =K6-L6 | N6: =IF(B6="","",IF(M6>0,"SURPLUS",IF(M6<0,"DEFISIT","AMAN")))
A7: 2 | B7: =IF(Pengaturan!$B$3+1>Pengaturan!$B$4,"",Pengaturan!$B$3+1) | C7: =IF(B7="","",TEXT(B7,"dddd")) | D7: =IF(B7="","",INT((B7-Pengaturan!$B$3)/7)+1) | E7: =IFERROR(VLOOKUP(B7,'Pagu Harian'!$A$4:$D$40,2,FALSE),Pengaturan!$B$13) | F7: =IF(B7="",0,SUMIF('Pengeluaran Pangan'!A:A,B7,'Pengeluaran Pangan'!G:G)) | G7: =IF(B7="",0,E7-F7) | H7: =IFERROR(VLOOKUP(B7,'Pagu Harian'!$A$4:$D$40,3,FALSE),Pengaturan!$B$14) | I7: =IF(B7="",0,SUMIF('Pengeluaran Operasional'!A:A,B7,'Pengeluaran Operasional'!G:G)) | J7: =IF(B7="",0,H7-I7) | K7: =E7+H7 | L7: =F7+I7 | M7: =K7-L7 | N7: =IF(B7="","",IF(M7>0,"SURPLUS",IF(M7<0,"DEFISIT","AMAN")))
A8: 3 | B8: =IF(Pengaturan!$B$3+2>Pengaturan!$B$4,"",Pengaturan!$B$3+2) | C8: =IF(B8="","",TEXT(B8,"dddd")) | D8: =IF(B8="","",INT((B8-Pengaturan!$B$3)/7)+1) | E8: =IFERROR(VLOOKUP(B8,'Pagu Harian'!$A$4:$D$40,2,FALSE),Pengaturan!$B$13) | F8: =IF(B8="",0,SUMIF('Pengeluaran Pangan'!A:A,B8,'Pengeluaran Pangan'!G:G)) | G8: =IF(B8="",0,E8-F8) | H8: =IFERROR(VLOOKUP(B8,'Pagu Harian'!$A$4:$D$40,3,FALSE),Pengaturan!$B$14) | I8: =IF(B8="",0,SUMIF('Pengeluaran Operasional'!A:A,B8,'Pengeluaran Operasional'!G:G)) | J8: =IF(B8="",0,H8-I8) | K8: =E8+H8 | L8: =F8+I8 | M8: =K8-L8 | N8: =IF(B8="","",IF(M8>0,"SURPLUS",IF(M8<0,"DEFISIT","AMAN")))
A9: 4 | B9: =IF(Pengaturan!$B$3+3>Pengaturan!$B$4,"",Pengaturan!$B$3+3) | C9: =IF(B9="","",TEXT(B9,"dddd")) | D9: =IF(B9="","",INT((B9-Pengaturan!$B$3)/7)+1) | E9: =IFERROR(VLOOKUP(B9,'Pagu Harian'!$A$4:$D$40,2,FALSE),Pengaturan!$B$13) | F9: =IF(B9="",0,SUMIF('Pengeluaran Pangan'!A:A,B9,'Pengeluaran Pangan'!G:G)) | G9: =IF(B9="",0,E9-F9) | H9: =IFERROR(VLOOKUP(B9,'Pagu Harian'!$A$4:$D$40,3,FALSE),Pengaturan!$B$14) | I9: =IF(B9="",0,SUMIF('Pengeluaran Operasional'!A:A,B9,'Pengeluaran Operasional'!G:G)) | J9: =IF(B9="",0,H9-I9) | K9: =E9+H9 | L9: =F9+I9 | M9: =K9-L9 | N9: =IF(B9="","",IF(M9>0,"SURPLUS",IF(M9<0,"DEFISIT","AMAN")))
A10: 5 | B10: =IF(Pengaturan!$B$3+4>Pengaturan!$B$4,"",Pengaturan!$B$3+4) | C10: =IF(B10="","",TEXT(B10,"dddd")) | D10: =IF(B10="","",INT((B10-Pengaturan!$B$3)/7)+1) | E10: =IFERROR(VLOOKUP(B10,'Pagu Harian'!$A$4:$D$40,2,FALSE),Pengaturan!$B$13) | F10: =IF(B10="",0,SUMIF('Pengeluaran Pangan'!A:A,B10,'Pengeluaran Pangan'!G:G)) | G10: =IF(B10="",0,E10-F10) | H10: =IFERROR(VLOOKUP(B10,'Pagu Harian'!$A$4:$D$40,3,FALSE),Pengaturan!$B$14) | I10: =IF(B10="",0,SUMIF('Pengeluaran Operasional'!A:A,B10,'Pengeluaran Operasional'!G:G)) | J10: =IF(B10="",0,H10-I10) | K10: =E10+H10 | L10: =F10+I10 | M10: =K10-L10 | N10: =IF(B10="","",IF(M10>0,"SURPLUS",IF(M10<0,"DEFISIT","AMAN")))
A11: 6 | B11: =IF(Pengaturan!$B$3+5>Pengaturan!$B$4,"",Pengaturan!$B$3+5) | C11: =IF(B11="","",TEXT(B11,"dddd")) | D11: =IF(B11="","",INT((B11-Pengaturan!$B$3)/7)+1) | E11: =IFERROR(VLOOKUP(B11,'Pagu Harian'!$A$4:$D$40,2,FALSE),Pengaturan!$B$13) | F11: =IF(B11="",0,SUMIF('Pengeluaran Pangan'!A:A,B11,'Pengeluaran Pangan'!G:G)) | G11: =IF(B11="",0,E11-F11) | H11: =IFERROR(VLOOKUP(B11,'Pagu Harian'!$A$4:$D$40,3,FALSE),Pengaturan!$B$14) | I11: =IF(B11="",0,SUMIF('Pengeluaran Operasional'!A:A,B11,'Pengeluaran Operasional'!G:G)) | J11: =IF(B11="",0,H11-I11) | K11: =E11+H11 | L11: =F11+I11 | M11: =K11-L11 | N11: =IF(B11="","",IF(M11>0,"SURPLUS",IF(M11<0,"DEFISIT","AMAN")))
A12: 7 | B12: =IF(Pengaturan!$B$3+6>Pengaturan!$B$4,"",Pengaturan!$B$3+6) | C12: =IF(B12="","",TEXT(B12,"dddd")) | D12: =IF(B12="","",INT((B12-Pengaturan!$B$3)/7)+1) | E12: =IFERROR(VLOOKUP(B12,'Pagu Harian'!$A$4:$D$40,2,FALSE),Pengaturan!$B$13) | F12: =IF(B12="",0,SUMIF('Pengeluaran Pangan'!A:A,B12,'Pengeluaran Pangan'!G:G)) | G12: =IF(B12="",0,E12-F12) | H12: =IFERROR(VLOOKUP(B12,'Pagu Harian'!$A$4:$D$40,3,FALSE),Pengaturan!$B$14) | I12: =IF(B12="",0,SUMIF('Pengeluaran Operasional'!A:A,B12,'Pengeluaran Operasional'!G:G)) | J12: =IF(B12="",0,H12-I12) | K12: =E12+H12 | L12: =F12+I12 | M12: =K12-L12 | N12: =IF(B12="","",IF(M12>0,"SURPLUS",IF(M12<0,"DEFISIT","AMAN")))
A13: 8 | B13: =IF(Pengaturan!$B$3+7>Pengaturan!$B$4,"",Pengaturan!$B$3+7) | C13: =IF(B13="","",TEXT(B13,"dddd")) | D13: =IF(B13="","",INT((B13-Pengaturan!$B$3)/7)+1) | E13: =IFERROR(VLOOKUP(B13,'Pagu Harian'!$A$4:$D$40,2,FALSE),Pengaturan!$B$13) | F13: =IF(B13="",0,SUMIF('Pengeluaran Pangan'!A:A,B13,'Pengeluaran Pangan'!G:G)) | G13: =IF(B13="",0,E13-F13) | H13: =IFERROR(VLOOKUP(B13,'Pagu Harian'!$A$4:$D$40,3,FALSE),Pengaturan!$B$14) | I13: =IF(B13="",0,SUMIF('Pengeluaran Operasional'!A:A,B13,'Pengeluaran Operasional'!G:G)) | J13: =IF(B13="",0,H13-I13) | K13: =E13+H13 | L13: =F13+I13 | M13: =K13-L13 | N13: =IF(B13="","",IF(M13>0,"SURPLUS",IF(M13<0,"DEFISIT","AMAN")))
A14: 9 | B14: =IF(Pengaturan!$B$3+8>Pengaturan!$B$4,"",Pengaturan!$B$3+8) | C14: =IF(B14="","",TEXT(B14,"dddd")) | D14: =IF(B14="","",INT((B14-Pengaturan!$B$3)/7)+1) | E14: =IFERROR(VLOOKUP(B14,'Pagu Harian'!$A$4:$D$40,2,FALSE),Pengaturan!$B$13) | F14: =IF(B14="",0,SUMIF('Pengeluaran Pangan'!A:A,B14,'Pengeluaran Pangan'!G:G)) | G14: =IF(B14="",0,E14-F14) | H14: =IFERROR(VLOOKUP(B14,'Pagu Harian'!$A$4:$D$40,3,FALSE),Pengaturan!$B$14) | I14: =IF(B14="",0,SUMIF('Pengeluaran Operasional'!A:A,B14,'Pengeluaran Operasional'!G:G)) | J14: =IF(B14="",0,H14-I14) | K14: =E14+H14 | L14: =F14+I14 | M14: =K14-L14 | N14: =IF(B14="","",IF(M14>0,"SURPLUS",IF(M14<0,"DEFISIT","AMAN")))
A15: 10 | B15: =IF(Pengaturan!$B$3+9>Pengaturan!$B$4,"",Pengaturan!$B$3+9) | C15: =IF(B15="","",TEXT(B15,"dddd")) | D15: =IF(B15="","",INT((B15-Pengaturan!$B$3)/7)+1) | E15: =IFERROR(VLOOKUP(B15,'Pagu Harian'!$A$4:$D$40,2,FALSE),Pengaturan!$B$13) | F15: =IF(B15="",0,SUMIF('Pengeluaran Pangan'!A:A,B15,'Pengeluaran Pangan'!G:G)) | G15: =IF(B15="",0,E15-F15) | H15: =IFERROR(VLOOKUP(B15,'Pagu Harian'!$A$4:$D$40,3,FALSE),Pengaturan!$B$14) | I15: =IF(B15="",0,SUMIF('Pengeluaran Operasional'!A:A,B15,'Pengeluaran Operasional'!G:G)) | J15: =IF(B15="",0,H15-I15) | K15: =E15+H15 | L15: =F15+I15 | M15: =K15-L15 | N15: =IF(B15="","",IF(M15>0,"SURPLUS",IF(M15<0,"DEFISIT","AMAN")))
A16: 11 | B16: =IF(Pengaturan!$B$3+10>Pengaturan!$B$4,"",Pengaturan!$B$3+10) | C16: =IF(B16="","",TEXT(B16,"dddd")) | D16: =IF(B16="","",INT((B16-Pengaturan!$B$3)/7)+1) | E16: =IFERROR(VLOOKUP(B16,'Pagu Harian'!$A$4:$D$40,2,FALSE),Pengaturan!$B$13) | F16: =IF(B16="",0,SUMIF('Pengeluaran Pangan'!A:A,B16,'Pengeluaran Pangan'!G:G)) | G16: =IF(B16="",0,E16-F16) | H16: =IFERROR(VLOOKUP(B16,'Pagu Harian'!$A$4:$D$40,3,FALSE),Pengaturan!$B$14) | I16: =IF(B16="",0,SUMIF('Pengeluaran Operasional'!A:A,B16,'Pengeluaran Operasional'!G:G)) | J16: =IF(B16="",0,H16-I16) | K16: =E16+H16 | L16: =F16+I16 | M16: =K16-L16 | N16: =IF(B16="","",IF(M16>0,"SURPLUS",IF(M16<0,"DEFISIT","AMAN")))
A17: 12 | B17: =IF(Pengaturan!$B$3+11>Pengaturan!$B$4,"",Pengaturan!$B$3+11) | C17: =IF(B17="","",TEXT(B17,"dddd")) | D17: =IF(B17="","",INT((B17-Pengaturan!$B$3)/7)+1) | E17: =IFERROR(VLOOKUP(B17,'Pagu Harian'!$A$4:$D$40,2,FALSE),Pengaturan!$B$13) | F17: =IF(B17="",0,SUMIF('Pengeluaran Pangan'!A:A,B17,'Pengeluaran Pangan'!G:G)) | G17: =IF(B17="",0,E17-F17) | H17: =IFERROR(VLOOKUP(B17,'Pagu Harian'!$A$4:$D$40,3,FALSE),Pengaturan!$B$14) | I17: =IF(B17="",0,SUMIF('Pengeluaran Operasional'!A:A,B17,'Pengeluaran Operasional'!G:G)) | J17: =IF(B17="",0,H17-I17) | K17: =E17+H17 | L17: =F17+I17 | M17: =K17-L17 | N17: =IF(B17="","",IF(M17>0,"SURPLUS",IF(M17<0,"DEFISIT","AMAN")))
A18: 13 | B18: =IF(Pengaturan!$B$3+12>Pengaturan!$B$4,"",Pengaturan!$B$3+12) | C18: =IF(B18="","",TEXT(B18,"dddd")) | D18: =IF(B18="","",INT((B18-Pengaturan!$B$3)/7)+1) | E18: =IFERROR(VLOOKUP(B18,'Pagu Harian'!$A$4:$D$40,2,FALSE),Pengaturan!$B$13) | F18: =IF(B18="",0,SUMIF('Pengeluaran Pangan'!A:A,B18,'Pengeluaran Pangan'!G:G)) | G18: =IF(B18="",0,E18-F18) | H18: =IFERROR(VLOOKUP(B18,'Pagu Harian'!$A$4:$D$40,3,FALSE),Pengaturan!$B$14) | I18: =IF(B18="",0,SUMIF('Pengeluaran Operasional'!A:A,B18,'Pengeluaran Operasional'!G:G)) | J18: =IF(B18="",0,H18-I18) | K18: =E18+H18 | L18: =F18+I18 | M18: =K18-L18 | N18: =IF(B18="","",IF(M18>0,"SURPLUS",IF(M18<0,"DEFISIT","AMAN")))
A19: 14 | B19: =IF(Pengaturan!$B$3+13>Pengaturan!$B$4,"",Pengaturan!$B$3+13) | C19: =IF(B19="","",TEXT(B19,"dddd")) | D19: =IF(B19="","",INT((B19-Pengaturan!$B$3)/7)+1) | E19: =IFERROR(VLOOKUP(B19,'Pagu Harian'!$A$4:$D$40,2,FALSE),Pengaturan!$B$13) | F19: =IF(B19="",0,SUMIF('Pengeluaran Pangan'!A:A,B19,'Pengeluaran Pangan'!G:G)) | G19: =IF(B19="",0,E19-F19) | H19: =IFERROR(VLOOKUP(B19,'Pagu Harian'!$A$4:$D$40,3,FALSE),Pengaturan!$B$14) | I19: =IF(B19="",0,SUMIF('Pengeluaran Operasional'!A:A,B19,'Pengeluaran Operasional'!G:G)) | J19: =IF(B19="",0,H19-I19) | K19: =E19+H19 | L19: =F19+I19 | M19: =K19-L19 | N19: =IF(B19="","",IF(M19>0,"SURPLUS",IF(M19<0,"DEFISIT","AMAN")))
A20: 15 | B20: =IF(Pengaturan!$B$3+14>Pengaturan!$B$4,"",Pengaturan!$B$3+14) | C20: =IF(B20="","",TEXT(B20,"dddd")) | D20: =IF(B20="","",INT((B20-Pengaturan!$B$3)/7)+1) | E20: =IFERROR(VLOOKUP(B20,'Pagu Harian'!$A$4:$D$40,2,FALSE),Pengaturan!$B$13) | F20: =IF(B20="",0,SUMIF('Pengeluaran Pangan'!A:A,B20,'Pengeluaran Pangan'!G:G)) | G20: =IF(B20="",0,E20-F20) | H20: =IFERROR(VLOOKUP(B20,'Pagu Harian'!$A$4:$D$40,3,FALSE),Pengaturan!$B$14) | I20: =IF(B20="",0,SUMIF('Pengeluaran Operasional'!A:A,B20,'Pengeluaran Operasional'!G:G)) | J20: =IF(B20="",0,H20-I20) | K20: =E20+H20 | L20: =F20+I20 | M20: =K20-L20 | N20: =IF(B20="","",IF(M20>0,"SURPLUS",IF(M20<0,"DEFISIT","AMAN")))
A21: 16 | B21: =IF(Pengaturan!$B$3+15>Pengaturan!$B$4,"",Pengaturan!$B$3+15) | C21: =IF(B21="","",TEXT(B21,"dddd")) | D21: =IF(B21="","",INT((B21-Pengaturan!$B$3)/7)+1) | E21: =IFERROR(VLOOKUP(B21,'Pagu Harian'!$A$4:$D$40,2,FALSE),Pengaturan!$B$13) | F21: =IF(B21="",0,SUMIF('Pengeluaran Pangan'!A:A,B21,'Pengeluaran Pangan'!G:G)) | G21: =IF(B21="",0,E21-F21) | H21: =IFERROR(VLOOKUP(B21,'Pagu Harian'!$A$4:$D$40,3,FALSE),Pengaturan!$B$14) | I21: =IF(B21="",0,SUMIF('Pengeluaran Operasional'!A:A,B21,'Pengeluaran Operasional'!G:G)) | J21: =IF(B21="",0,H21-I21) | K21: =E21+H21 | L21: =F21+I21 | M21: =K21-L21 | N21: =IF(B21="","",IF(M21>0,"SURPLUS",IF(M21<0,"DEFISIT","AMAN")))
A22: 17 | B22: =IF(Pengaturan!$B$3+16>Pengaturan!$B$4,"",Pengaturan!$B$3+16) | C22: =IF(B22="","",TEXT(B22,"dddd")) | D22: =IF(B22="","",INT((B22-Pengaturan!$B$3)/7)+1) | E22: =IFERROR(VLOOKUP(B22,'Pagu Harian'!$A$4:$D$40,2,FALSE),Pengaturan!$B$13) | F22: =IF(B22="",0,SUMIF('Pengeluaran Pangan'!A:A,B22,'Pengeluaran Pangan'!G:G)) | G22: =IF(B22="",0,E22-F22) | H22: =IFERROR(VLOOKUP(B22,'Pagu Harian'!$A$4:$D$40,3,FALSE),Pengaturan!$B$14) | I22: =IF(B22="",0,SUMIF('Pengeluaran Operasional'!A:A,B22,'Pengeluaran Operasional'!G:G)) | J22: =IF(B22="",0,H22-I22) | K22: =E22+H22 | L22: =F22+I22 | M22: =K22-L22 | N22: =IF(B22="","",IF(M22>0,"SURPLUS",IF(M22<0,"DEFISIT","AMAN")))
A23: 18 | B23: =IF(Pengaturan!$B$3+17>Pengaturan!$B$4,"",Pengaturan!$B$3+17) | C23: =IF(B23="","",TEXT(B23,"dddd")) | D23: =IF(B23="","",INT((B23-Pengaturan!$B$3)/7)+1) | E23: =IFERROR(VLOOKUP(B23,'Pagu Harian'!$A$4:$D$40,2,FALSE),Pengaturan!$B$13) | F23: =IF(B23="",0,SUMIF('Pengeluaran Pangan'!A:A,B23,'Pengeluaran Pangan'!G:G)) | G23: =IF(B23="",0,E23-F23) | H23: =IFERROR(VLOOKUP(B23,'Pagu Harian'!$A$4:$D$40,3,FALSE),Pengaturan!$B$14) | I23: =IF(B23="",0,SUMIF('Pengeluaran Operasional'!A:A,B23,'Pengeluaran Operasional'!G:G)) | J23: =IF(B23="",0,H23-I23) | K23: =E23+H23 | L23: =F23+I23 | M23: =K23-L23 | N23: =IF(B23="","",IF(M23>0,"SURPLUS",IF(M23<0,"DEFISIT","AMAN")))
A24: 19 | B24: =IF(Pengaturan!$B$3+18>Pengaturan!$B$4,"",Pengaturan!$B$3+18) | C24: =IF(B24="","",TEXT(B24,"dddd")) | D24: =IF(B24="","",INT((B24-Pengaturan!$B$3)/7)+1) | E24: =IFERROR(VLOOKUP(B24,'Pagu Harian'!$A$4:$D$40,2,FALSE),Pengaturan!$B$13) | F24: =IF(B24="",0,SUMIF('Pengeluaran Pangan'!A:A,B24,'Pengeluaran Pangan'!G:G)) | G24: =IF(B24="",0,E24-F24) | H24: =IFERROR(VLOOKUP(B24,'Pagu Harian'!$A$4:$D$40,3,FALSE),Pengaturan!$B$14) | I24: =IF(B24="",0,SUMIF('Pengeluaran Operasional'!A:A,B24,'Pengeluaran Operasional'!G:G)) | J24: =IF(B24="",0,H24-I24) | K24: =E24+H24 | L24: =F24+I24 | M24: =K24-L24 | N24: =IF(B24="","",IF(M24>0,"SURPLUS",IF(M24<0,"DEFISIT","AMAN")))
A25: 20 | B25: =IF(Pengaturan!$B$3+19>Pengaturan!$B$4,"",Pengaturan!$B$3+19) | C25: =IF(B25="","",TEXT(B25,"dddd")) | D25: =IF(B25="","",INT((B25-Pengaturan!$B$3)/7)+1) | E25: =IFERROR(VLOOKUP(B25,'Pagu Harian'!$A$4:$D$40,2,FALSE),Pengaturan!$B$13) | F25: =IF(B25="",0,SUMIF('Pengeluaran Pangan'!A:A,B25,'Pengeluaran Pangan'!G:G)) | G25: =IF(B25="",0,E25-F25) | H25: =IFERROR(VLOOKUP(B25,'Pagu Harian'!$A$4:$D$40,3,FALSE),Pengaturan!$B$14) | I25: =IF(B25="",0,SUMIF('Pengeluaran Operasional'!A:A,B25,'Pengeluaran Operasional'!G:G)) | J25: =IF(B25="",0,H25-I25) | K25: =E25+H25 | L25: =F25+I25 | M25: =K25-L25 | N25: =IF(B25="","",IF(M25>0,"SURPLUS",IF(M25<0,"DEFISIT","AMAN")))
A26: 21 | B26: =IF(Pengaturan!$B$3+20>Pengaturan!$B$4,"",Pengaturan!$B$3+20) | C26: =IF(B26="","",TEXT(B26,"dddd")) | D26: =IF(B26="","",INT((B26-Pengaturan!$B$3)/7)+1) | E26: =IFERROR(VLOOKUP(B26,'Pagu Harian'!$A$4:$D$40,2,FALSE),Pengaturan!$B$13) | F26: =IF(B26="",0,SUMIF('Pengeluaran Pangan'!A:A,B26,'Pengeluaran Pangan'!G:G)) | G26: =IF(B26="",0,E26-F26) | H26: =IFERROR(VLOOKUP(B26,'Pagu Harian'!$A$4:$D$40,3,FALSE),Pengaturan!$B$14) | I26: =IF(B26="",0,SUMIF('Pengeluaran Operasional'!A:A,B26,'Pengeluaran Operasional'!G:G)) | J26: =IF(B26="",0,H26-I26) | K26: =E26+H26 | L26: =F26+I26 | M26: =K26-L26 | N26: =IF(B26="","",IF(M26>0,"SURPLUS",IF(M26<0,"DEFISIT","AMAN")))
A27: 22 | B27: =IF(Pengaturan!$B$3+21>Pengaturan!$B$4,"",Pengaturan!$B$3+21) | C27: =IF(B27="","",TEXT(B27,"dddd")) | D27: =IF(B27="","",INT((B27-Pengaturan!$B$3)/7)+1) | E27: =IFERROR(VLOOKUP(B27,'Pagu Harian'!$A$4:$D$40,2,FALSE),Pengaturan!$B$13) | F27: =IF(B27="",0,SUMIF('Pengeluaran Pangan'!A:A,B27,'Pengeluaran Pangan'!G:G)) | G27: =IF(B27="",0,E27-F27) | H27: =IFERROR(VLOOKUP(B27,'Pagu Harian'!$A$4:$D$40,3,FALSE),Pengaturan!$B$14) | I27: =IF(B27="",0,SUMIF('Pengeluaran Operasional'!A:A,B27,'Pengeluaran Operasional'!G:G)) | J27: =IF(B27="",0,H27-I27) | K27: =E27+H27 | L27: =F27+I27 | M27: =K27-L27 | N27: =IF(B27="","",IF(M27>0,"SURPLUS",IF(M27<0,"DEFISIT","AMAN")))
A28: 23 | B28: =IF(Pengaturan!$B$3+22>Pengaturan!$B$4,"",Pengaturan!$B$3+22) | C28: =IF(B28="","",TEXT(B28,"dddd")) | D28: =IF(B28="","",INT((B28-Pengaturan!$B$3)/7)+1) | E28: =IFERROR(VLOOKUP(B28,'Pagu Harian'!$A$4:$D$40,2,FALSE),Pengaturan!$B$13) | F28: =IF(B28="",0,SUMIF('Pengeluaran Pangan'!A:A,B28,'Pengeluaran Pangan'!G:G)) | G28: =IF(B28="",0,E28-F28) | H28: =IFERROR(VLOOKUP(B28,'Pagu Harian'!$A$4:$D$40,3,FALSE),Pengaturan!$B$14) | I28: =IF(B28="",0,SUMIF('Pengeluaran Operasional'!A:A,B28,'Pengeluaran Operasional'!G:G)) | J28: =IF(B28="",0,H28-I28) | K28: =E28+H28 | L28: =F28+I28 | M28: =K28-L28 | N28: =IF(B28="","",IF(M28>0,"SURPLUS",IF(M28<0,"DEFISIT","AMAN")))
A29: 24 | B29: =IF(Pengaturan!$B$3+23>Pengaturan!$B$4,"",Pengaturan!$B$3+23) | C29: =IF(B29="","",TEXT(B29,"dddd")) | D29: =IF(B29="","",INT((B29-Pengaturan!$B$3)/7)+1) | E29: =IFERROR(VLOOKUP(B29,'Pagu Harian'!$A$4:$D$40,2,FALSE),Pengaturan!$B$13) | F29: =IF(B29="",0,SUMIF('Pengeluaran Pangan'!A:A,B29,'Pengeluaran Pangan'!G:G)) | G29: =IF(B29="",0,E29-F29) | H29: =IFERROR(VLOOKUP(B29,'Pagu Harian'!$A$4:$D$40,3,FALSE),Pengaturan!$B$14) | I29: =IF(B29="",0,SUMIF('Pengeluaran Operasional'!A:A,B29,'Pengeluaran Operasional'!G:G)) | J29: =IF(B29="",0,H29-I29) | K29: =E29+H29 | L29: =F29+I29 | M29: =K29-L29 | N29: =IF(B29="","",IF(M29>0,"SURPLUS",IF(M29<0,"DEFISIT","AMAN")))
A30: 25 | B30: =IF(Pengaturan!$B$3+24>Pengaturan!$B$4,"",Pengaturan!$B$3+24) | C30: =IF(B30="","",TEXT(B30,"dddd")) | D30: =IF(B30="","",INT((B30-Pengaturan!$B$3)/7)+1) | E30: =IFERROR(VLOOKUP(B30,'Pagu Harian'!$A$4:$D$40,2,FALSE),Pengaturan!$B$13) | F30: =IF(B30="",0,SUMIF('Pengeluaran Pangan'!A:A,B30,'Pengeluaran Pangan'!G:G)) | G30: =IF(B30="",0,E30-F30) | H30: =IFERROR(VLOOKUP(B30,'Pagu Harian'!$A$4:$D$40,3,FALSE),Pengaturan!$B$14) | I30: =IF(B30="",0,SUMIF('Pengeluaran Operasional'!A:A,B30,'Pengeluaran Operasional'!G:G)) | J30: =IF(B30="",0,H30-I30) | K30: =E30+H30 | L30: =F30+I30 | M30: =K30-L30 | N30: =IF(B30="","",IF(M30>0,"SURPLUS",IF(M30<0,"DEFISIT","AMAN")))
A31: 26 | B31: =IF(Pengaturan!$B$3+25>Pengaturan!$B$4,"",Pengaturan!$B$3+25) | C31: =IF(B31="","",TEXT(B31,"dddd")) | D31: =IF(B31="","",INT((B31-Pengaturan!$B$3)/7)+1) | E31: =IFERROR(VLOOKUP(B31,'Pagu Harian'!$A$4:$D$40,2,FALSE),Pengaturan!$B$13) | F31: =IF(B31="",0,SUMIF('Pengeluaran Pangan'!A:A,B31,'Pengeluaran Pangan'!G:G)) | G31: =IF(B31="",0,E31-F31) | H31: =IFERROR(VLOOKUP(B31,'Pagu Harian'!$A$4:$D$40,3,FALSE),Pengaturan!$B$14) | I31: =IF(B31="",0,SUMIF('Pengeluaran Operasional'!A:A,B31,'Pengeluaran Operasional'!G:G)) | J31: =IF(B31="",0,H31-I31) | K31: =E31+H31 | L31: =F31+I31 | M31: =K31-L31 | N31: =IF(B31="","",IF(M31>0,"SURPLUS",IF(M31<0,"DEFISIT","AMAN")))
A32: 27 | B32: =IF(Pengaturan!$B$3+26>Pengaturan!$B$4,"",Pengaturan!$B$3+26) | C32: =IF(B32="","",TEXT(B32,"dddd")) | D32: =IF(B32="","",INT((B32-Pengaturan!$B$3)/7)+1) | E32: =IFERROR(VLOOKUP(B32,'Pagu Harian'!$A$4:$D$40,2,FALSE),Pengaturan!$B$13) | F32: =IF(B32="",0,SUMIF('Pengeluaran Pangan'!A:A,B32,'Pengeluaran Pangan'!G:G)) | G32: =IF(B32="",0,E32-F32) | H32: =IFERROR(VLOOKUP(B32,'Pagu Harian'!$A$4:$D$40,3,FALSE),Pengaturan!$B$14) | I32: =IF(B32="",0,SUMIF('Pengeluaran Operasional'!A:A,B32,'Pengeluaran Operasional'!G:G)) | J32: =IF(B32="",0,H32-I32) | K32: =E32+H32 | L32: =F32+I32 | M32: =K32-L32 | N32: =IF(B32="","",IF(M32>0,"SURPLUS",IF(M32<0,"DEFISIT","AMAN")))
A33: 28 | B33: =IF(Pengaturan!$B$3+27>Pengaturan!$B$4,"",Pengaturan!$B$3+27) | C33: =IF(B33="","",TEXT(B33,"dddd")) | D33: =IF(B33="","",INT((B33-Pengaturan!$B$3)/7)+1) | E33: =IFERROR(VLOOKUP(B33,'Pagu Harian'!$A$4:$D$40,2,FALSE),Pengaturan!$B$13) | F33: =IF(B33="",0,SUMIF('Pengeluaran Pangan'!A:A,B33,'Pengeluaran Pangan'!G:G)) | G33: =IF(B33="",0,E33-F33) | H33: =IFERROR(VLOOKUP(B33,'Pagu Harian'!$A$4:$D$40,3,FALSE),Pengaturan!$B$14) | I33: =IF(B33="",0,SUMIF('Pengeluaran Operasional'!A:A,B33,'Pengeluaran Operasional'!G:G)) | J33: =IF(B33="",0,H33-I33) | K33: =E33+H33 | L33: =F33+I33 | M33: =K33-L33 | N33: =IF(B33="","",IF(M33>0,"SURPLUS",IF(M33<0,"DEFISIT","AMAN")))
A34: 29 | B34: =IF(Pengaturan!$B$3+28>Pengaturan!$B$4,"",Pengaturan!$B$3+28) | C34: =IF(B34="","",TEXT(B34,"dddd")) | D34: =IF(B34="","",INT((B34-Pengaturan!$B$3)/7)+1) | E34: =IFERROR(VLOOKUP(B34,'Pagu Harian'!$A$4:$D$40,2,FALSE),Pengaturan!$B$13) | F34: =IF(B34="",0,SUMIF('Pengeluaran Pangan'!A:A,B34,'Pengeluaran Pangan'!G:G)) | G34: =IF(B34="",0,E34-F34) | H34: =IFERROR(VLOOKUP(B34,'Pagu Harian'!$A$4:$D$40,3,FALSE),Pengaturan!$B$14) | I34: =IF(B34="",0,SUMIF('Pengeluaran Operasional'!A:A,B34,'Pengeluaran Operasional'!G:G)) | J34: =IF(B34="",0,H34-I34) | K34: =E34+H34 | L34: =F34+I34 | M34: =K34-L34 | N34: =IF(B34="","",IF(M34>0,"SURPLUS",IF(M34<0,"DEFISIT","AMAN")))
A35: 30 | B35: =IF(Pengaturan!$B$3+29>Pengaturan!$B$4,"",Pengaturan!$B$3+29) | C35: =IF(B35="","",TEXT(B35,"dddd")) | D35: =IF(B35="","",INT((B35-Pengaturan!$B$3)/7)+1) | E35: =IFERROR(VLOOKUP(B35,'Pagu Harian'!$A$4:$D$40,2,FALSE),Pengaturan!$B$13) | F35: =IF(B35="",0,SUMIF('Pengeluaran Pangan'!A:A,B35,'Pengeluaran Pangan'!G:G)) | G35: =IF(B35="",0,E35-F35) | H35: =IFERROR(VLOOKUP(B35,'Pagu Harian'!$A$4:$D$40,3,FALSE),Pengaturan!$B$14) | I35: =IF(B35="",0,SUMIF('Pengeluaran Operasional'!A:A,B35,'Pengeluaran Operasional'!G:G)) | J35: =IF(B35="",0,H35-I35) | K35: =E35+H35 | L35: =F35+I35 | M35: =K35-L35 | N35: =IF(B35="","",IF(M35>0,"SURPLUS",IF(M35<0,"DEFISIT","AMAN")))
A36: 31 | B36: =IF(Pengaturan!$B$3+30>Pengaturan!$B$4,"",Pengaturan!$B$3+30) | C36: =IF(B36="","",TEXT(B36,"dddd")) | D36: =IF(B36="","",INT((B36-Pengaturan!$B$3)/7)+1) | E36: =IFERROR(VLOOKUP(B36,'Pagu Harian'!$A$4:$D$40,2,FALSE),Pengaturan!$B$13) | F36: =IF(B36="",0,SUMIF('Pengeluaran Pangan'!A:A,B36,'Pengeluaran Pangan'!G:G)) | G36: =IF(B36="",0,E36-F36) | H36: =IFERROR(VLOOKUP(B36,'Pagu Harian'!$A$4:$D$40,3,FALSE),Pengaturan!$B$14) | I36: =IF(B36="",0,SUMIF('Pengeluaran Operasional'!A:A,B36,'Pengeluaran Operasional'!G:G)) | J36: =IF(B36="",0,H36-I36) | K36: =E36+H36 | L36: =F36+I36 | M36: =K36-L36 | N36: =IF(B36="","",IF(M36>0,"SURPLUS",IF(M36<0,"DEFISIT","AMAN")))
B38: TOTAL | E38: =SUM(E6:E36) | F38: =SUM(F6:F36) | G38: =SUM(G6:G36) | H38: =SUM(H6:H36) | I38: =SUM(I6:I36) | J38: =SUM(J6:J36) | K38: =SUM(K6:K36) | L38: =SUM(L6:L36) | M38: =SUM(M6:M36)
B39: RATA-RATA/HARI | E39: =IFERROR(AVERAGEIF(B6:B36,"<>",E6:E36),0) | F39: =IFERROR(AVERAGEIF(B6:B36,"<>",F6:F36),0) | G39: =IFERROR(AVERAGEIF(B6:B36,"<>",G6:G36),0) | H39: =IFERROR(AVERAGEIF(B6:B36,"<>",H6:H36),0) | I39: =IFERROR(AVERAGEIF(B6:B36,"<>",I6:I36),0) | J39: =IFERROR(AVERAGEIF(B6:B36,"<>",J6:J36),0) | K39: =IFERROR(AVERAGEIF(B6:B36,"<>",K6:K36),0) | L39: =IFERROR(AVERAGEIF(B6:B36,"<>",L6:L36),0) | M39: =IFERROR(AVERAGEIF(B6:B36,"<>",M6:M36),0)

Sheet Rekap Mingguan
A1: REKAP MINGGUAN PENGELUARAN
A2: Agregasi mingguan otomatis. Surplus = hemat, Defisit = boros
A3: Minggu Ke | B3: Periode | C3: Pagu Pangan | D3: Aktual Pangan | E3: Selisih Pangan | F3: Pagu Operasional | G3: Aktual Operasional | H3: Selisih Operasional | I3: Total Pagu | J3: Total Aktual | K3: Surplus/Defisit | L3: Status
A4: 1 | B4: =IF(Pengaturan!$B$3+0>Pengaturan!$B$4,"",TEXT(Pengaturan!$B$3+0,"dd mmm")&" - "&TEXT(MIN(Pengaturan!$B$3+6,Pengaturan!$B$4),"dd mmm")) | C4: =SUMIF('Rekap Harian'!$D$6:$D$36,A4,'Rekap Harian'!$E$6:$E$36) | D4: =SUMIF('Rekap Harian'!$D$6:$D$36,A4,'Rekap Harian'!$F$6:$F$36) | E4: =C4-D4 | F4: =SUMIF('Rekap Harian'!$D$6:$D$36,A4,'Rekap Harian'!$H$6:$H$36) | G4: =SUMIF('Rekap Harian'!$D$6:$D$36,A4,'Rekap Harian'!$I$6:$I$36) | H4: =F4-G4 | I4: =C4+F4 | J4: =D4+G4 | K4: =I4-J4 | L4: =IF(I4=0,"",IF(K4>0,"SURPLUS",IF(K4<0,"DEFISIT","AMAN")))
A5: 2 | B5: =IF(Pengaturan!$B$3+7>Pengaturan!$B$4,"",TEXT(Pengaturan!$B$3+7,"dd mmm")&" - "&TEXT(MIN(Pengaturan!$B$3+13,Pengaturan!$B$4),"dd mmm")) | C5: =SUMIF('Rekap Harian'!$D$6:$D$36,A5,'Rekap Harian'!$E$6:$E$36) | D5: =SUMIF('Rekap Harian'!$D$6:$D$36,A5,'Rekap Harian'!$F$6:$F$36) | E5: =C5-D5 | F5: =SUMIF('Rekap Harian'!$D$6:$D$36,A5,'Rekap Harian'!$H$6:$H$36) | G5: =SUMIF('Rekap Harian'!$D$6:$D$36,A5,'Rekap Harian'!$I$6:$I$36) | H5: =F5-G5 | I5: =C5+F5 | J5: =D5+G5 | K5: =I5-J5 | L5: =IF(I5=0,"",IF(K5>0,"SURPLUS",IF(K5<0,"DEFISIT","AMAN")))
A6: 3 | B6: =IF(Pengaturan!$B$3+14>Pengaturan!$B$4,"",TEXT(Pengaturan!$B$3+14,"dd mmm")&" - "&TEXT(MIN(Pengaturan!$B$3+20,Pengaturan!$B$4),"dd mmm")) | C6: =SUMIF('Rekap Harian'!$D$6:$D$36,A6,'Rekap Harian'!$E$6:$E$36) | D6: =SUMIF('Rekap Harian'!$D$6:$D$36,A6,'Rekap Harian'!$F$6:$F$36) | E6: =C6-D6 | F6: =SUMIF('Rekap Harian'!$D$6:$D$36,A6,'Rekap Harian'!$H$6:$H$36) | G6: =SUMIF('Rekap Harian'!$D$6:$D$36,A6,'Rekap Harian'!$I$6:$I$36) | H6: =F6-G6 | I6: =C6+F6 | J6: =D6+G6 | K6: =I6-J6 | L6: =IF(I6=0,"",IF(K6>0,"SURPLUS",IF(K6<0,"DEFISIT","AMAN")))
A7: 4 | B7: =IF(Pengaturan!$B$3+21>Pengaturan!$B$4,"",TEXT(Pengaturan!$B$3+21,"dd mmm")&" - "&TEXT(MIN(Pengaturan!$B$3+27,Pengaturan!$B$4),"dd mmm")) | C7: =SUMIF('Rekap Harian'!$D$6:$D$36,A7,'Rekap Harian'!$E$6:$E$36) | D7: =SUMIF('Rekap Harian'!$D$6:$D$36,A7,'Rekap Harian'!$F$6:$F$36) | E7: =C7-D7 | F7: =SUMIF('Rekap Harian'!$D$6:$D$36,A7,'Rekap Harian'!$H$6:$H$36) | G7: =SUMIF('Rekap Harian'!$D$6:$D$36,A7,'Rekap Harian'!$I$6:$I$36) | H7: =F7-G7 | I7: =C7+F7 | J7: =D7+G7 | K7: =I7-J7 | L7: =IF(I7=0,"",IF(K7>0,"SURPLUS",IF(K7<0,"DEFISIT","AMAN")))
A8: 5 | B8: =IF(Pengaturan!$B$3+28>Pengaturan!$B$4,"",TEXT(Pengaturan!$B$3+28,"dd mmm")&" - "&TEXT(MIN(Pengaturan!$B$3+34,Pengaturan!$B$4),"dd mmm")) | C8: =SUMIF('Rekap Harian'!$D$6:$D$36,A8,'Rekap Harian'!$E$6:$E$36) | D8: =SUMIF('Rekap Harian'!$D$6:$D$36,A8,'Rekap Harian'!$F$6:$F$36) | E8: =C8-D8 | F8: =SUMIF('Rekap Harian'!$D$6:$D$36,A8,'Rekap Harian'!$H$6:$H$36) | G8: =SUMIF('Rekap Harian'!$D$6:$D$36,A8,'Rekap Harian'!$I$6:$I$36) | H8: =F8-G8 | I8: =C8+F8 | J8: =D8+G8 | K8: =I8-J8 | L8: =IF(I8=0,"",IF(K8>0,"SURPLUS",IF(K8<0,"DEFISIT","AMAN")))
A10: TOTAL | C10: =SUM(C4:C8) | D10: =SUM(D4:D8) | E10: =SUM(E4:E8) | F10: =SUM(F4:F8) | G10: =SUM(G4:G8) | H10: =SUM(H4:H8) | I10: =SUM(I4:I8) | J10: =SUM(J4:J8) | K10: =SUM(K4:K8)

Sheet Grafik
A1: VISUALISASI LAPORAN KEUANGAN
A2: Grafik profesional di sebelah kanan dan bawah tabel data
A4: 1. Tren Harian - Pangan & Operasional vs Pagu
A5: Tgl | B5: Aktual Pangan | C5: Pagu Pangan | D5: Aktual Operasional | E5: Pagu Operasional
A6: ='Rekap Harian'!B6 | B6: ='Rekap Harian'!F6 | C6: ='Rekap Harian'!E6 | D6: ='Rekap Harian'!I6 | E6: ='Rekap Harian'!H6
A7: ='Rekap Harian'!B7 | B7: ='Rekap Harian'!F7 | C7: ='Rekap Harian'!E7 | D7: ='Rekap Harian'!I7 | E7: ='Rekap Harian'!H7
A8: ='Rekap Harian'!B8 | B8: ='Rekap Harian'!F8 | C8: ='Rekap Harian'!E8 | D8: ='Rekap Harian'!I8 | E8: ='Rekap Harian'!H8
A9: ='Rekap Harian'!B9 | B9: ='Rekap Harian'!F9 | C9: ='Rekap Harian'!E9 | D9: ='Rekap Harian'!I9 | E9: ='Rekap Harian'!H9
A10: ='Rekap Harian'!B10 | B10: ='Rekap Harian'!F10 | C10: ='Rekap Harian'!E10 | D10: ='Rekap Harian'!I10 | E10: ='Rekap Harian'!H10
A11: ='Rekap Harian'!B11 | B11: ='Rekap Harian'!F11 | C11: ='Rekap Harian'!E11 | D11: ='Rekap Harian'!I11 | E11: ='Rekap Harian'!H11
A12: ='Rekap Harian'!B12 | B12: ='Rekap Harian'!F12 | C12: ='Rekap Harian'!E12 | D12: ='Rekap Harian'!I12 | E12: ='Rekap Harian'!H12
A13: ='Rekap Harian'!B13 | B13: ='Rekap Harian'!F13 | C13: ='Rekap Harian'!E13 | D13: ='Rekap Harian'!I13 | E13: ='Rekap Harian'!H13
A14: ='Rekap Harian'!B14 | B14: ='Rekap Harian'!F14 | C14: ='Rekap Harian'!E14 | D14: ='Rekap Harian'!I14 | E14: ='Rekap Harian'!H14
A15: ='Rekap Harian'!B15 | B15: ='Rekap Harian'!F15 | C15: ='Rekap Harian'!E15 | D15: ='Rekap Harian'!I15 | E15: ='Rekap Harian'!H15
A16: ='Rekap Harian'!B16 | B16: ='Rekap Harian'!F16 | C16: ='Rekap Harian'!E16 | D16: ='Rekap Harian'!I16 | E16: ='Rekap Harian'!H16
A17: ='Rekap Harian'!B17 | B17: ='Rekap Harian'!F17 | C17: ='Rekap Harian'!E17 | D17: ='Rekap Harian'!I17 | E17: ='Rekap Harian'!H17
... A36: ='Rekap Harian'!B36 | B36: ='Rekap Harian'!F36 | C36: ='Rekap Harian'!E36 | D36: ='Rekap Harian'!I36 | E36: ='Rekap Harian'!H36
A38: 2. Surplus vs Defisit Per Hari
A39: Tgl | B39: Surplus (Rp) | C39: Defisit (Rp)
A40: ='Rekap Harian'!B6 | B40: =IF('Rekap Harian'!M6>0,'Rekap Harian'!M6,0) | C40: =IF('Rekap Harian'!M6<0,-'Rekap Harian'!M6,0)
A41: ='Rekap Harian'!B7 | B41: =IF('Rekap Harian'!M7>0,'Rekap Harian'!M7,0) | C41: =IF('Rekap Harian'!M7<0,-'Rekap Harian'!M7,0)
A42: ='Rekap Harian'!B8 | B42: =IF('Rekap Harian'!M8>0,'Rekap Harian'!M8,0) | C42: =IF('Rekap Harian'!M8<0,-'Rekap Harian'!M8,0)
A43: ='Rekap Harian'!B9 | B43: =IF('Rekap Harian'!M9>0,'Rekap Harian'!M9,0) | C43: =IF('Rekap Harian'!M9<0,-'Rekap Harian'!M9,0)
A44: ='Rekap Harian'!B10 | B44: =IF('Rekap Harian'!M10>0,'Rekap Harian'!M10,0) | C44: =IF('Rekap Harian'!M10<0,-'Rekap Harian'!M10,0)
A45: ='Rekap Harian'!B11 | B45: =IF('Rekap Harian'!M11>0,'Rekap Harian'!M11,0) | C45: =IF('Rekap Harian'!M11<0,-'Rekap Harian'!M11,0)
A46: ='Rekap Harian'!B12 | B46: =IF('Rekap Harian'!M12>0,'Rekap Harian'!M12,0) | C46: =IF('Rekap Harian'!M12<0,-'Rekap Harian'!M12,0)
A47: ='Rekap Harian'!B13 | B47: =IF('Rekap Harian'!M13>0,'Rekap Harian'!M13,0) | C47: =IF('Rekap Harian'!M13<0,-'Rekap Harian'!M13,0)
A48: ='Rekap Harian'!B14 | B48: =IF('Rekap Harian'!M14>0,'Rekap Harian'!M14,0) | C48: =IF('Rekap Harian'!M14<0,-'Rekap Harian'!M14,0)
A49: ='Rekap Harian'!B15 | B49: =IF('Rekap Harian'!M15>0,'Rekap Harian'!M15,0) | C49: =IF('Rekap Harian'!M15<0,-'Rekap Harian'!M15,0)
A50: ='Rekap Harian'!B16 | B50: =IF('Rekap Harian'!M16>0,'Rekap Harian'!M16,0) | C50: =IF('Rekap Harian'!M16<0,-'Rekap Harian'!M16,0)
A51: ='Rekap Harian'!B17 | B51: =IF('Rekap Harian'!M17>0,'Rekap Harian'!M17,0) | C51: =IF('Rekap Harian'!M17<0,-'Rekap Harian'!M17,0)
... A70: ='Rekap Harian'!B36 | B70: =IF('Rekap Harian'!M36>0,'Rekap Harian'!M36,0) | C70: =IF('Rekap Harian'!M36<0,-'Rekap Harian'!M36,0)
A72: 3. Rekap Mingguan - Aktual vs Pagu
A73: Minggu | B73: Aktual Pangan | C73: Pagu Pangan | D73: Aktual Operasional | E73: Pagu Operasional
A74: ="Mg "&A4 | B74: ='Rekap Mingguan'!D4 | C74: ='Rekap Mingguan'!C4 | D74: ='Rekap Mingguan'!G4 | E74: ='Rekap Mingguan'!F4
A75: ="Mg "&A5 | B75: ='Rekap Mingguan'!D5 | C75: ='Rekap Mingguan'!C5 | D75: ='Rekap Mingguan'!G5 | E75: ='Rekap Mingguan'!F5
A76: ="Mg "&A6 | B76: ='Rekap Mingguan'!D6 | C76: ='Rekap Mingguan'!C6 | D76: ='Rekap Mingguan'!G6 | E76: ='Rekap Mingguan'!F6
A77: ="Mg "&A7 | B77: ='Rekap Mingguan'!D7 | C77: ='Rekap Mingguan'!C7 | D77: ='Rekap Mingguan'!G7 | E77: ='Rekap Mingguan'!F7
A78: ="Mg "&A8 | B78: ='Rekap Mingguan'!D8 | C78: ='Rekap Mingguan'!C8 | D78: ='Rekap Mingguan'!G8 | E78: ='Rekap Mingguan'!F8
A80: 4. Komposisi Pengeluaran
...

Sheet Pengaturan
A1: PENGATURAN LAPORAN KEUANGAN
A2: Master konfigurasi - edit bagian ini untuk menyesuaikan laporan
A3: Periode Mulai | B3: 46143 | C3: <- edit tanggal
A4: Periode Selesai | B4: 46173 | C4: <- edit tanggal
A5: Jumlah Hari Operasi | B5: =B4-B3+1 | C5: (otomatis)
A7: DANA ANGGARAN
A8: Dana Total Bahan Pangan | B8: 60000000 | C8: <- edit total dana
A9: Dana Total Operasional | B9: 25000000 | C9: <- edit total dana
A10: Total Dana Keseluruhan | B10: =B8+B9
A12: PAGU DEFAULT / HARI (SEHARUSNYA)
A13: Pagu Default Pangan/Hari | B13: =IF(B5=0,0,B8/B5) | C13: = Dana Pangan / Jumlah Hari
A14: Pagu Default Operasional/Hari | B14: =IF(B5=0,0,B9/B5) | C14: = Dana Operasional / Jumlah Hari
A15: Pagu Default Total/Hari | B15: =B13+B14 | C15: = Pangan + Operasional
A17: INFORMASI ORGANISASI
A18: Nama Instansi | B18: SPPG Battuwinangun
A19: Alamat | B19: -
A20: Penanggung Jawab | B20: -
A21: Periode Laporan | B21: =TEXT(B3,"dd mmm yyyy")&" s/d "&TEXT(B4,"dd mmm yyyy")
A23: CATATAN:
A24: - Edit hanya di kolom B pada baris yang bertanda <- edit
A25: - Pagu per hari bisa berbeda-beda, diatur di sheet 'Pagu Harian'
A26: - Jika Pagu Harian kosong untuk tanggal tertentu, dipakai pagu default
A27: - Dashboard, Rekap Harian, & Grafik update otomatis

Sheet Pagu Harian
A1: PAGU HARIAN PENGELUARAN
A2: Set pagu per tanggal. Biarkan kosong -> pakai pagu default dari sheet Pengaturan
A3: Tanggal | B3: Pagu Pangan (Rp) | C3: Pagu Operasional (Rp) | D3: Pagu Total (Rp) | E3: Keterangan
A4: =IF(Pengaturan!$B$3+0>Pengaturan!$B$4,"",Pengaturan!$B$3+0) | B4: =IF(A4="","",Pengaturan!$B$13) | C4: =IF(A4="","",Pengaturan!$B$14) | D4: =IF(A4="","",B4+C4)
A5: =IF(Pengaturan!$B$3+1>Pengaturan!$B$4,"",Pengaturan!$B$3+1) | B5: =IF(A5="","",Pengaturan!$B$13) | C5: =IF(A5="","",Pengaturan!$B$14) | D5: =IF(A5="","",B5+C5)
A6: =IF(Pengaturan!$B$3+2>Pengaturan!$B$4,"",Pengaturan!$B$3+2) | B6: =IF(A6="","",Pengaturan!$B$13) | C6: =IF(A6="","",Pengaturan!$B$14) | D6: =IF(A6="","",B6+C6)
A7: =IF(Pengaturan!$B$3+3>Pengaturan!$B$4,"",Pengaturan!$B$3+3) | B7: =IF(A7="","",Pengaturan!$B$13) | C7: =IF(A7="","",Pengaturan!$B$14) | D7: =IF(A7="","",B7+C7)
A8: =IF(Pengaturan!$B$3+4>Pengaturan!$B$4,"",Pengaturan!$B$3+4) | B8: =IF(A8="","",Pengaturan!$B$13) | C8: =IF(A8="","",Pengaturan!$B$14) | D8: =IF(A8="","",B8+C8)
A9: =IF(Pengaturan!$B$3+5>Pengaturan!$B$4,"",Pengaturan!$B$3+5) | B9: =IF(A9="","",Pengaturan!$B$13) | C9: =IF(A9="","",Pengaturan!$B$14) | D9: =IF(A9="","",B9+C9)
A10: =IF(Pengaturan!$B$3+6>Pengaturan!$B$4,"",Pengaturan!$B$3+6) | B10: =IF(A10="","",Pengaturan!$B$13) | C10: =IF(A10="","",Pengaturan!$B$14) | D10: =IF(A10="","",B10+C10)
A11: =IF(Pengaturan!$B$3+7>Pengaturan!$B$4,"",Pengaturan!$B$3+7) | B11: =IF(A11="","",Pengaturan!$B$13) | C11: =IF(A11="","",Pengaturan!$B$14) | D11: =IF(A11="","",B11+C11)
A12: =IF(Pengaturan!$B$3+8>Pengaturan!$B$4,"",Pengaturan!$B$3+8) | B12: =IF(A12="","",Pengaturan!$B$13) | C12: =IF(A12="","",Pengaturan!$B$14) | D12: =IF(A12="","",B12+C12)
A13: =IF(Pengaturan!$B$3+9>Pengaturan!$B$4,"",Pengaturan!$B$3+9) | B13: =IF(A13="","",Pengaturan!$B$13) | C13: =IF(A13="","",Pengaturan!$B$14) | D13: =IF(A13="","",B13+C13)
A14: =IF(Pengaturan!$B$3+10>Pengaturan!$B$4,"",Pengaturan!$B$3+10) | B14: =IF(A14="","",Pengaturan!$B$13) | C14: =IF(A14="","",Pengaturan!$B$14) | D14: =IF(A14="","",B14+C14)
A15: =IF(Pengaturan!$B$3+11>Pengaturan!$B$4,"",Pengaturan!$B$3+11) | B15: =IF(A15="","",Pengaturan!$B$13) | C15: =IF(A15="","",Pengaturan!$B$14) | D15: =IF(A15="","",B15+C15)
A16: =IF(Pengaturan!$B$3+12>Pengaturan!$B$4,"",Pengaturan!$B$3+12) | B16: =IF(A16="","",Pengaturan!$B$13) | C16: =IF(A16="","",Pengaturan!$B$14) | D16: =IF(A16="","",B16+C16)
A17: =IF(Pengaturan!$B$3+13>Pengaturan!$B$4,"",Pengaturan!$B$3+13) | B17: =IF(A17="","",Pengaturan!$B$13) | C17: =IF(A17="","",Pengaturan!$B$14) | D17: =IF(A17="","",B17+C17)
A18: =IF(Pengaturan!$B$3+14>Pengaturan!$B$4,"",Pengaturan!$B$3+14) | B18: =IF(A18="","",Pengaturan!$B$13) | C18: =IF(A18="","",Pengaturan!$B$14) | D18: =IF(A18="","",B18+C18)
A19: =IF(Pengaturan!$B$3+15>Pengaturan!$B$4,"",Pengaturan!$B$3+15) | B19: =IF(A19="","",Pengaturan!$B$13) | C19: =IF(A19="","",Pengaturan!$B$14) | D19: =IF(A19="","",B19+C19)
A20: =IF(Pengaturan!$B$3+16>Pengaturan!$B$4,"",Pengaturan!$B$3+16) | B20: =IF(A20="","",Pengaturan!$B$13) | C20: =IF(A20="","",Pengaturan!$B$14) | D20: =IF(A20="","",B20+C20)
A21: =IF(Pengaturan!$B$3+17>Pengaturan!$B$4,"",Pengaturan!$B$3+17) | B21: =IF(A21="","",Pengaturan!$B$13) | C21: =IF(A21="","",Pengaturan!$B$14) | D21: =IF(A21="","",B21+C21)
A22: =IF(Pengaturan!$B$3+18>Pengaturan!$B$4,"",Pengaturan!$B$3+18) | B22: =IF(A22="","",Pengaturan!$B$13) | C22: =IF(A22="","",Pengaturan!$B$14) | D22: =IF(A22="","",B22+C22)
A23: =IF(Pengaturan!$B$3+19>Pengaturan!$B$4,"",Pengaturan!$B$3+19) | B23: =IF(A23="","",Pengaturan!$B$13) | C23: =IF(A23="","",Pengaturan!$B$14) | D23: =IF(A23="","",B23+C23)
A24: =IF(Pengaturan!$B$3+20>Pengaturan!$B$4,"",Pengaturan!$B$3+20) | B24: =IF(A24="","",Pengaturan!$B$13) | C24: =IF(A24="","",Pengaturan!$B$14) | D24: =IF(A24="","",B24+C24)
A25: =IF(Pengaturan!$B$3+21>Pengaturan!$B$4,"",Pengaturan!$B$3+21) | B25: =IF(A25="","",Pengaturan!$B$13) | C25: =IF(A25="","",Pengaturan!$B$14) | D25: =IF(A25="","",B25+C25)
A26: =IF(Pengaturan!$B$3+22>Pengaturan!$B$4,"",Pengaturan!$B$3+22) | B26: =IF(A26="","",Pengaturan!$B$13) | C26: =IF(A26="","",Pengaturan!$B$14) | D26: =IF(A26="","",B26+C26)
A27: =IF(Pengaturan!$B$3+23>Pengaturan!$B$4,"",Pengaturan!$B$3+23) | B27: =IF(A27="","",Pengaturan!$B$13) | C27: =IF(A27="","",Pengaturan!$B$14) | D27: =IF(A27="","",B27+C27)
A28: =IF(Pengaturan!$B$3+24>Pengaturan!$B$4,"",Pengaturan!$B$3+24) | B28: =IF(A28="","",Pengaturan!$B$13) | C28: =IF(A28="","",Pengaturan!$B$14) | D28: =IF(A28="","",B28+C28)
A29: =IF(Pengaturan!$B$3+25>Pengaturan!$B$4,"",Pengaturan!$B$3+25) | B29: =IF(A29="","",Pengaturan!$B$13) | C29: =IF(A29="","",Pengaturan!$B$14) | D29: =IF(A29="","",B29+C29)
A30: =IF(Pengaturan!$B$3+26>Pengaturan!$B$4,"",Pengaturan!$B$3+26) | B30: =IF(A30="","",Pengaturan!$B$13) | C30: =IF(A30="","",Pengaturan!$B$14) | D30: =IF(A30="","",B30+C30)
A31: =IF(Pengaturan!$B$3+27>Pengaturan!$B$4,"",Pengaturan!$B$3+27) | B31: =IF(A31="","",Pengaturan!$B$13) | C31: =IF(A31="","",Pengaturan!$B$14) | D31: =IF(A31="","",B31+C31)
A32: =IF(Pengaturan!$B$3+28>Pengaturan!$B$4,"",Pengaturan!$B$3+28) | B32: =IF(A32="","",Pengaturan!$B$13) | C32: =IF(A32="","",Pengaturan!$B$14) | D32: =IF(A32="","",B32+C32)
A33: =IF(Pengaturan!$B$3+29>Pengaturan!$B$4,"",Pengaturan!$B$3+29) | B33: =IF(A33="","",Pengaturan!$B$13) | C33: =IF(A33="","",Pengaturan!$B$14) | D33: =IF(A33="","",B33+C33)
A34: =IF(Pengaturan!$B$3+30>Pengaturan!$B$4,"",Pengaturan!$B$3+30) | B34: =IF(A34="","",Pengaturan!$B$13) | C34: =IF(A34="","",Pengaturan!$B$14) | D34: =IF(A34="","",B34+C34)
A36: TOTAL | B36: =SUM(B4:B34) | C36: =SUM(C4:C34) | D36: =SUM(D4:D34)

Sheet Pengeluaran Pangan
A1: LOG PENGELUARAN BAHAN PANGAN
A2: Catat semua transaksi bahan pangan di sini
A3: Tanggal | B3: Item / Bahan | C3: Kategori | D3: Qty | E3: Satuan | F3: Harga Satuan (Rp) | G3: Jumlah (Rp) | H3: Keterangan
A4: 46143 | B4: Beras premium | C4: Karbohidrat | D4: 50 | E4: kg | F4: 15000 | G4: =D4*F4 | H4: Stok awal
A5: 46143 | B5: Ayam potong | C5: Protein Hewani | D5: 20 | E5: kg | F5: 38000 | G5: =D5*F5 | H5: Menu hari 1
A6: 46144 | B6: Sayur bayam | C6: Sayuran | D6: 15 | E6: ikat | F6: 3500 | G6: =D6*F6
A7: 46144 | B7: Telur ayam | C7: Protein Hewani | D7: 8 | E7: kg | F7: 28000 | G7: =D7*F7
A8: 46145 | B8: Ikan nila | C8: Protein Hewani | D8: 18 | E8: kg | F8: 32000 | G8: =D8*F8
A9: 46145 | B9: Wortel | C9: Sayuran | D9: 10 | E9: kg | F9: 8000 | G9: =D9*F9
A10: 46146 | B10: Tempe | C10: Protein Nabati | D10: 12 | E10: kg | F10: 12000 | G10: =D10*F10
A11: 46146 | B11: Minyak goreng | C11: Bumbu | D11: 5 | E11: liter | F11: 18000 | G11: =D11*F11
A12: 46147 | B12: Buah pisang | C12: Buah | D12: 20 | E12: sisir | F12: 15000 | G12: =D12*F12
A13: 46147 | B13: Bumbu dapur | C13: Bumbu | D13: 1 | E13: paket | F13: 150000 | G13: =D13*F13 | H13: Bawang, cabe
F125: TOTAL PENGELUARAN PANGAN | G125: =SUM(G4:G123)

Sheet Pengeluaran Operasional
A1: LOG PENGELUARAN OPERASIONAL
A2: Catat semua biaya operasional non-bahan pangan di sini
A3: Tanggal | B3: Deskripsi | C3: Kategori | D3: Qty | E3: Satuan | F3: Harga Satuan (Rp) | G3: Jumlah (Rp) | H3: Keterangan
A4: 46143 | B4: Gas LPG 12kg | C4: Bahan Bakar | D4: 2 | E4: tabung | F4: 185000 | G4: =D4*F4 | H4: Memasak
A5: 46144 | B5: Gaji juru masak | C5: Tenaga Kerja | D5: 1 | E5: orang | F5: 150000 | G5: =D5*F5 | H5: Harian
A6: 46144 | B6: Listrik & air | C6: Utilitas | D6: 1 | E6: bulan | F6: 450000 | G6: =D6*F6
A7: 46145 | B7: Sabun cuci & pembersih | C7: Sanitasi | D7: 5 | E7: pcs | F7: 25000 | G7: =D7*F7
A8: 46146 | B8: Kemasan makan | C8: Packaging | D8: 200 | E8: pcs | F8: 1500 | G8: =D8*F8
A9: 46147 | B9: Transportasi distribusi | C9: Transportasi | D9: 1 | E9: trip | F9: 120000 | G9: =D9*F9
A10: 46148 | B10: Alat masak (spatula) | C10: Peralatan | D10: 3 | E10: pcs | F10: 35000 | G10: =D10*F10
A11: 46149 | B11: Perawatan kompor | C11: Pemeliharaan | D11: 1 | E11: kali | F11: 200000 | G11: =D11*F11
F123: TOTAL PENGELUARAN OPERASIONAL | G123: =SUM(G4:G121)

Sheet Kategori
A1: DAFTAR KATEGORI (REFERENSI)
A2: Gunakan nama kategori yang konsisten agar SUMIF akurat
A3: Kategori Bahan Pangan | B3: Kategori Operasional
A4: Karbohidrat | B4: Bahan Bakar
A5: Protein Hewani | B5: Tenaga Kerja
A6: Protein Nabati | B6: Utilitas
A7: Sayuran | B7: Sanitasi
A8: Buah | B8: Packaging
A9: Susu & Olahan | B9: Transportasi
A10: Bumbu | B10: Peralatan
A11: Minuman | B11: Pemeliharaan
A12: Lain-lain | B12: Administrasi
B13: Lain-lain
